Workbook
Name M_to_MM: '[1]WFM - Wild Oats'!$L$54

Sheet Income Statement
A2: Consolidated Income Statements
A3: (in US$ millions except per share amounts) | G3: Actuals | N3: Estimates
A5: Period Ending December 31 | D5: 2018 | E5: =D5+1 -> 2019 | F5: =E5+1 -> 2020 | G5: =F5+1 -> 2021 | H5: =G5+1 -> 2022 | I5: =H5+1 -> 2023 | J5: =I5+1 -> 2024 | K5: =J5+1 -> 2025 | L5: =K5+1 -> 2026 | ... Q5: =P5+1 -> 2031
A6: Revenue
B7: Automotive Sales | D7: 17632 | E7: 19952 | F7: 26184 | G7: 44125 | H7: 67210 | I7: 78509 | J7: 72480 | K7: 65821
C8: Y/Y growth (%) | E8: =(E7-D7)/D7 -> 0.13157895 | F8: =(F7-E7)/E7 -> 0.31234964 | G8: =(G7-F7)/F7 -> 0.68518943 | H8: =(H7-G7)/G7 -> 0.5231728 | I8: =(I7-H7)/H7 -> 0.16811486 | J8: =(J7-I7)/I7 -> -0.076793743 | K8: =(K7-J7)/J7 -> -0.09187362
B9: Automotive Regulatory Credits | D9: 0 | E9: 0 | F9: 0 | G9: 1465 | H9: 1776 | I9: 1790 | J9: 2763 | K9: 1993 | M9: Try to project the individual line items later. See Pignataro p.36 for clues.
C10: Y/Y growth (%) | E10: 0 | F10: 0 | G10: 0 | H10: =H9/G9-1 -> 0.21228669 | I10: =I9/H9-1 -> 0.0078828829 | J10: =J9/I9-1 -> 0.54357542 | K10: =K9/J9-1 -> -0.27868259
B11: Automotive Leasings | D11: 883 | E11: 869 | F11: 1052 | G11: 1642 | H11: 2476 | I11: 2120 | J11: 1827 | K11: 1712
C12: Y/Y growth (%) | E12: =(E11-D11)/D11 -> -0.01585504 | F12: =(F11-E11)/E11 -> 0.21058688 | G12: =(G11-F11)/F11 -> 0.5608365 | H12: =(H11-G11)/G11 -> 0.50791717 | I12: =(I11-H11)/H11 -> -0.14378029 | J12: =(J11-I11)/I11 -> -0.13820755 | K12: =(K11-J11)/J11 -> -0.062944718
B13: Total Automotive Revenues | D13: =D7+D11+D9 -> 18515 | E13: =E7+E11+E9 -> 20821 | F13: =F7+F11+F9 -> 27236 | G13: =G7+G11+G9 -> 47232 | H13: =H7+H11+H9 -> 71462 | I13: =I7+I11+I9 -> 82419 | J13: =J7+J11+J9 -> 77070 | K13: =K7+K11+K9 -> 69526
C14: Y/Y growth (%) | E14: =(E13-D13)/D13 -> 0.12454766 | F14: =(F13-E13)/E13 -> 0.3081024 | G14: =(G13-F13)/F13 -> 0.73417536 | H14: =(H13-G13)/G13 -> 0.51299966 | I14: =(I13-H13)/H13 -> 0.15332624 | J14: =(J13-I13)/I13 -> -0.064900084 | K14: =(K13-J13)/J13 -> -0.09788504
B15: Energy Generation and Storage | D15: 1555 | E15: 1531 | F15: 1994 | G15: 2789 | H15: 3909 | I15: 6035 | J15: 10086 | K15: 12771
C16: Y/Y growth (%) | E16: =(E15-D15)/D15 -> -0.015434084 | F16: =(F15-E15)/E15 -> 0.30241672 | G16: =(G15-F15)/F15 -> 0.39869609 | H16: =(H15-G15)/G15 -> 0.40157763 | I16: =(I15-H15)/H15 -> 0.54387311 | J16: =(J15-I15)/I15 -> 0.67125104 | K16: =(K15-J15)/J15 -> 0.26621059
B17: Services and Other | D17: 1391 | E17: 2226 | F17: 2306 | G17: 3802 | H17: 6091 | I17: 8319 | J17: 10534 | K17: 12530
C18: Y/Y growth (%) | E18: =(E17-D17)/D17 -> 0.60028756 | F18: =(F17-E17)/E17 -> 0.035938904 | G18: =(G17-F17)/F17 -> 0.64874241 | H18: =(H17-G17)/G17 -> 0.60205155 | I18: =(I17-H17)/H17 -> 0.36578559 | J18: =(J17-I17)/I17 -> 0.26625796 | K18: =(K17-J17)/J17 -> 0.18948168
B19: Total Revenues | D19: =D13+D15+D17 -> 21461 | E19: =E13+E15+E17 -> 24578 | F19: =F13+F15+F17 -> 31536 | G19: =G13+G15+G17 -> 53823 | H19: =H13+H15+H17 -> 81462 | I19: =I13+I15+I17 -> 96773 | J19: =J13+J15+J17 -> 97690 | K19: =K13+K15+K17 -> 94827 | L19: 111580 | M19: 169190 | N19: =M19*(1+N20) -> 211487.5 | O19: =N19*(1+O20) -> 264359.38 | P19: =O19*(1+P20) -> 330449.22 | Q19: =P19*(1+Q20) -> 413061.52
C20: Y/Y Total Rev Growth (Decline) (%) | E20: =(E19-D19)/D19 -> 0.1452402 | F20: =(F19-E19)/E19 -> 0.28309871 | G20: =(G19-F19)/F19 -> 0.70671613 | H20: =(H19-G19)/G19 -> 0.51351653 | I20: =(I19-H19)/H19 -> 0.18795267 | J20: =(J19-I19)/I19 -> 0.0094757835 | K20: =(K19-J19)/J19 -> -0.029306992 | L20: =(L19-K19)/K19 -> 0.17666909 | M20: =(M19-L19)/L19 -> 0.51631117 | N20: 0.25 | O20: =N20 -> 0.25 | P20: =O20 -> 0.25 | Q20: =P20 -> 0.25
A21: Cost of revenues (goods sold)
B22: Automotive Sales | D22: 13686 | E22: 15939 | F22: 19696 | G22: 32415 | H22: 49599 | I22: 65121 | J22: 61870 | K22: 56267
B23: Automotive Leasing | D23: 488 | E23: 459 | F23: 563 | G23: 978 | H23: 1509 | I23: 1268 | J23: 1003 | K23: 898 | M23: Try to project the individual line items later. See Pignataro p.42 for clues.
B24: Total automotive cost of revenues (goods sold) | D24: =D22+D23 -> 14174 | E24: =E22+E23 -> 16398 | F24: =F22+F23 -> 20259 | G24: =G22+G23 -> 33393 | H24: =H22+H23 -> 51108 | I24: =I22+I23 -> 66389 | J24: =J22+J23 -> 62873 | K24: =K22+K23 -> 57165
B25: Energy generation and storage | D25: 1365 | E25: 1341 | F25: 1976 | G25: 2918 | H25: 3621 | I25: 4894 | J25: 7446 | K25: 8969
B26: Services and other | D26: 1880 | E26: 2770 | F26: 2671 | G26: 3906 | H26: 5880 | I26: 7830 | J26: 9921 | K26: 11599
B27: Total Cost of goods sold (minus Depreciation)* | D27: =D24+D25+D26-D44 -> 15518 | E27: =E24+E25+E26-E44 -> 18355 | F27: =F24+F25+F26-F44 -> 22584 | G27: =G24+G25+G26-G44 -> 37306 | H27: =H24+H25+H26-H44 -> 56862 | I27: =I24+I25+I26-I44 -> 74446 | J27: =J24+J25+J26-J44 -> 74872 | K27: =K24+K25+K26-K44 -> 71585 | L27: =L19*L29 -> 85517.635 | M27: =M19*M29 -> 129671.34 | N27: =N19*N29 -> 162089.18 | O27: =O19*O29 -> 202611.48 | P27: =P19*P29 -> 253264.35 | Q27: =Q19*Q29 -> 316580.43
C28: COGS Growth (Decline) % Y/Y | E28: =E27/D27-1 -> 0.18281995 | F28: =F27/E27-1 -> 0.23040044 | G28: =G27/F27-1 -> 0.65187744 | H28: =H27/G27-1 -> 0.52420522 | I28: =I27/H27-1 -> 0.30923991 | J28: =J27/I27-1 -> 0.0057222685 | K28: =K27/J27-1 -> -0.043901592
C29: COGS as a % of net sales | D29: =D27/D19 -> 0.72307907 | E29: =E27/E19 -> 0.74680609 | F29: =F27/F19 -> 0.71613394 | G29: =G27/G19 -> 0.69312376 | H29: =H27/H19 -> 0.69801871 | I29: =I27/I19 -> 0.76928482 | J29: =J27/J19 -> 0.7664244 | K29: =K27/K19 -> 0.75490103 | L29: =$J$29 -> 0.7664244 | M29: =L29 -> 0.7664244 | N29: =M29 -> 0.7664244 | O29: =N29 -> 0.7664244 | P29: =O29 -> 0.7664244 | Q29: =P29 -> 0.7664244
B30: Gross profit | D30: =D19-D27 -> 5943 | E30: =E19-E27 -> 6223 | F30: =F19-F27 -> 8952 | G30: =G19-G27 -> 16517 | H30: =H19-H27 -> 24600 | I30: =I19-I27 -> 22327 | J30: =J19-J27 -> 22818 | K30: =K19-K27 -> 23242 | ... Q30: =Q19-Q27 -> 96481.092
C31: Gross profit margin (%) | D31: =D30/D19 -> 0.27692093 | E31: =E30/E19 -> 0.25319391 | F31: =F30/F19 -> 0.28386606 | G31: =G30/G19 -> 0.30687624 | H31: =H30/H19 -> 0.30198129 | I31: =I30/I19 -> 0.23071518 | J31: =J30/J19 -> 0.2335756 | K31: =K30/K19 -> 0.24509897 | ... Q31: =Q30/Q19 -> 0.2335756
A32: Operating expenses
B33: Research and Development | D33: 1460 | E33: 1343 | F33: 1491 | G33: 2593 | H33: 3075 | I33: 3969 | J33: 4540 | K33: 6411 | L33: =L19*L34 -> 7810.6 | M33: =M19*M34 -> 11843.3 | N33: =N19*N34 -> 14804.125 | O33: =O19*O34 -> 18505.156 | P33: =P19*P34 -> 23131.445 | Q33: =Q19*Q34 -> 28914.307
C34: R&D as a % of Total Rev | D34: =D33/D19 -> 0.068030381 | E34: =E33/E19 -> 0.054642363 | F34: =F33/F19 -> 0.0472793 | G34: =G33/G19 -> 0.04817643 | H34: =H33/H19 -> 0.037747661 | I34: =I33/I19 -> 0.041013506 | J34: =J33/J19 -> 0.046473539 | K34: =K33/K19 -> 0.067607327 | L34: 0.07 | M34: =L34 -> 0.07 | N34: =M34 -> 0.07 | O34: =N34 -> 0.07 | P34: =O34 -> 0.07 | Q34: =P34 -> 0.07
C35: R&D Growth (Decline) % Y/Y | E35: =E33/D33-1 -> -0.080136986 | F35: =F33/E33-1 -> 0.11020104 | G35: =G33/F33-1 -> 0.73910127 | H35: =H33/G33-1 -> 0.18588508 | I35: =I33/H33-1 -> 0.29073171 | J35: =J33/I33-1 -> 0.14386495 | K35: =K33/J33-1 -> 0.41211454
B36: Selling, general and administrative | D36: 2835 | E36: 2646 | F36: 3145 | G36: 4517 | H36: 3946 | I36: 4800 | J36: 5150 | K36: 5834 | L36: =L19*L37 -> 6864.6875 | M36: =M19*M37 -> 10409.002 | N36: =N19*N37 -> 13011.253 | O36: =O19*O37 -> 13936.44 | P36: =P19*P37 -> 17420.549 | Q36: =Q19*Q37 -> 21775.687
C37: Selling, general and administrative as a % of Total Rev | D37: =D36/D19 -> 0.13210009 | E37: =E36/E19 -> 0.10765725 | F37: =F36/F19 -> 0.099727296 | G37: =G36/G19 -> 0.08392323 | H37: =H36/H19 -> 0.048439763 | I37: =I36/I19 -> 0.049600612 | J37: =J36/J19 -> 0.052717781 | K37: =K36/K19 -> 0.061522562 | L37: =K37 -> 0.061522562 | M37: =L37 -> 0.061522562 | N37: =M37 -> 0.061522562 | O37: =$J$37 -> 0.052717781 | P37: =$J$37 -> 0.052717781 | Q37: =$J$37 -> 0.052717781
C38: SG&A Growth (Decline) % Y/Y | E38: =E36/D36-1 -> -0.066666667 | F38: =F36/E36-1 -> 0.18858655 | G38: =G36/F36-1 -> 0.43624801 | H38: =H36/G36-1 -> -0.12641133 | I38: =I36/H36-1 -> 0.21642169 | J38: =J36/I36-1 -> 0.072916667 | K38: =K36/J36-1 -> 0.13281553
B39: Restructuring and other | D39: 135 | E39: 149 | F39: 0 | G39: -27 | H39: 176 | I39: 0 | J39: 684 | K39: 494 | L39: =L19*L40 -> 581.27453 | M39: =M19*M40 -> 881.39306 | N39: =N19*N40 -> 1101.7413 | O39: =O19*O40 -> 1377.1767 | P39: =P19*P40 -> 1721.4708 | Q39: =Q19*Q40 -> 2151.8385
C40: Restructuring and other expense as a % of Total Rev | D40: =D39/D19 -> 0.0062904804 | E40: =E39/E19 -> 0.0060623322 | F40: =F39/F19 -> 0 | G40: =G39/G19 -> -0.00050164428 | H40: =H39/H19 -> 0.0021605166 | I40: =I39/I19 -> 0 | J40: =J39/J19 -> 0.0070017402 | K40: =K39/K19 -> 0.0052094867 | L40: =K40 -> 0.0052094867 | M40: =L40 -> 0.0052094867 | N40: =M40 -> 0.0052094867 | O40: =N40 -> 0.0052094867 | P40: =O40 -> 0.0052094867 | Q40: =P40 -> 0.0052094867
B41: Total operating expenses | D41: =D33+D36+D39 -> 4430 | E41: =E33+E36+E39 -> 4138 | F41: =F33+F36+F39 -> 4636 | G41: =G33+G36+G39 -> 7083 | H41: =H33+H36+H39 -> 7197 | I41: =I33+I36+I39 -> 8769 | J41: =J33+J36+J39 -> 10374 | K41: =K33+K36+K39 -> 12739 | ... Q41: =Q33+Q36+Q39 -> 52841.832
B42: EBITDA* | D42: =D30-D41 -> 1513 | E42: =E30-E41 -> 2085 | F42: =F30-F41 -> 4316 | G42: =G30-G41 -> 9434 | H42: =H30-H41 -> 17403 | I42: =I30-I41 -> 13558 | J42: =J30-J41 -> 12444 | K42: =K30-K41 -> 10503 | ... Q42: =Q30-Q41 -> 43639.26
...

Sheet Cash Flow Statement
A2: Consolidated Statements of Cash Flows
A3: ='Income Statement'!A3 -> (in US$ millions except per share amounts) | G3: Actuals | N3: Estimates
A5: Period Ending December 31 | D5: ='Income Statement'!D5 -> 2018 | E5: ='Income Statement'!E5 -> 2019 | F5: ='Income Statement'!F5 -> 2020 | G5: ='Income Statement'!G5 -> 2021 | H5: ='Income Statement'!H5 -> 2022 | I5: ='Income Statement'!I5 -> 2023 | J5: ='Income Statement'!J5 -> 2024 | K5: ='Income Statement'!K5 -> 2025 | L5: 2026E | M5: 2027E | N5: 2028E | O5: 2029E | P5: 2030E | Q5: 2031E
A6: Cash flows from operating activities
B7: Net income | D7: ='Income Statement'!D57 -> -1063 | E7: ='Income Statement'!E57 -> -775 | F7: ='Income Statement'!F57 -> 862 | G7: ='Income Statement'!G57 -> 5644 | H7: ='Income Statement'!H57 -> 12587 | I7: ='Income Statement'!I57 -> 14974 | J7: ='Income Statement'!J57 -> 7153 | K7: ='Income Statement'!K57 -> 3855 | ... Q7: ='Income Statement'!Q57 -> 23747.528
B8: Depreciation and amortization | D8: ='Income Statement'!D44 -> 1901 | E8: ='Income Statement'!E44 -> 2154 | F8: ='Income Statement'!F44 -> 2322 | G8: ='Income Statement'!G44 -> 2911 | H8: ='Income Statement'!H44 -> 3747 | I8: ='Income Statement'!I44 -> 4667 | J8: ='Income Statement'!J44 -> 5368 | K8: ='Income Statement'!K44 -> 6148 | ... Q8: ='Income Statement'!Q44 -> 13710.654
B9: Stock-based compensation | D9: 749 | E9: 898 | F9: 1734 | G9: 2121 | H9: 1560 | I9: 1812 | J9: 1999 | K9: 2825 | L9: ='Income Statement'!L41*'Cash Flow Statement'!L10 -> 3383.2944 | M9: ='Income Statement'!M41*'Cash Flow Statement'!M10 -> 5130.1271 | N9: ='Income Statement'!N41*'Cash Flow Statement'!N10 -> 6412.6589 | O9: ='Income Statement'!O41*'Cash Flow Statement'!O10 -> 7499.6493 | P9: ='Income Statement'!P41*'Cash Flow Statement'!P10 -> 9374.5616 | Q9: ='Income Statement'!Q41*'Cash Flow Statement'!Q10 -> 11718.202
C10: % of Total Operating Expenses | D10: =D9/'Income Statement'!D41 -> 0.16907449 | E10: =E9/'Income Statement'!E41 -> 0.21701305 | F10: =F9/'Income Statement'!F41 -> 0.37402934 | G10: =G9/'Income Statement'!G41 -> 0.29944939 | H10: =H9/'Income Statement'!H41 -> 0.21675698 | I10: =I9/'Income Statement'!I41 -> 0.20663702 | J10: =J9/'Income Statement'!J41 -> 0.19269327 | K10: =K9/'Income Statement'!K41 -> 0.22175995 | L10: =K10 -> 0.22175995 | M10: =L10 -> 0.22175995 | N10: =M10 -> 0.22175995 | O10: =N10 -> 0.22175995 | P10: =O10 -> 0.22175995 | Q10: =P10 -> 0.22175995
B11: Amortization of debt discounts and issuance costs | D11: 159 | E11: 188 | F11: 180 | G11: 0 | H11: 0 | I11: 0 | J11: 0 | K11: 0
B12: Inventory and Purchase commitment write-downs | D12: 85 | E12: 193 | F12: 202 | G12: 140 | H12: 177 | I12: 463 | J12: 335 | K12: 362 | L12: =AVERAGE(I12:K12) -> 386.66667 | M12: =L12 -> 386.66667 | N12: =M12 -> 386.66667 | O12: =N12 -> 386.66667 | P12: =O12 -> 386.66667 | Q12: =P12 -> 386.66667
B13: Loss on disposal of fixed assets | D13: 162 | E13: 146 | F13: 117 | G13: 0 | H13: =G13 -> 0 | I13: =H13 -> 0 | J13: =I13 -> 0 | K13: =J13 -> 0
B14: Foreign currency transaction net unrealized loss (gain) | D14: -2 | E14: -48 | F14: 114 | G14: -55 | H14: 81 | I14: -144 | J14: -73 | K14: 452 | L14: =I14 -> -144 | M14: =J14 -> -73 | N14: =K14 -> 452 | O14: =L14 -> -144 | P14: =M14 -> -73 | Q14: =N14 -> 452
B15: Non-cash interest and other operating activities | D15: 49 | E15: 186 | F15: 228 | G15: 245 | H15: 340 | I15: 81 | J15: 172 | K15: 272 | L15: =L16*'Income Statement'!L19 -> 272 | M15: =M16*'Income Statement'!M19 -> 412.43664 | N15: =N16*'Income Statement'!N19 -> 515.5458 | O15: =O16*'Income Statement'!O19 -> 644.43225 | P15: =P16*'Income Statement'!P19 -> 805.54031 | Q15: =Q16*'Income Statement'!Q19 -> 1006.9254
C16: % of Total Revenues | D16: =D15/'Income Statement'!E19 -> 0.0019936529 | E16: =E15/'Income Statement'!F19 -> 0.0058980213 | F16: =F15/'Income Statement'!G19 -> 0.0042361072 | G16: =G15/'Income Statement'!H19 -> 0.0030075373 | H16: =H15/'Income Statement'!I19 -> 0.0035133767 | I16: =I15/'Income Statement'!J19 -> 0.00082915344 | J16: =J15/'Income Statement'!K19 -> 0.0018138294 | K16: =K15/'Income Statement'!L19 -> 0.0024377129 | L16: =K16 -> 0.0024377129 | M16: =L16 -> 0.0024377129 | N16: =M16 -> 0.0024377129 | O16: =N16 -> 0.0024377129 | P16: =O16 -> 0.0024377129 | Q16: =P16 -> 0.0024377129
B17: Operating cash flow related to repayment of discounted convertible senior notes | D17: 0 | E17: -188 | F17: 0 | G17: 0 | H17: 0 | I17: 0 | J17: 0 | K17: 0 | L17: =K17 -> 0 | M17: =L17 -> 0 | N17: =M17 -> 0 | O17: =N17 -> 0 | P17: =O17 -> 0 | Q17: =P17 -> 0
B18: Deferred income taxes | D18: 0 | E18: 0 | F18: 0 | G18: -149 | H18: -196 | I18: -6349 | J18: 477 | K18: 123 | L18: =K18 -> 123 | M18: =L18 -> 123 | N18: =M18 -> 123 | O18: =N18 -> 123 | P18: =O18 -> 123 | Q18: =P18 -> 123
B19: Digital asset loss (gain), net | D19: 0 | E19: 0 | F19: 0 | G19: -27 | H19: 140 | I19: 0 | J19: -589 | K19: 68 | L19: =K19 -> 68 | M19: =L19 -> 68 | N19: =M19 -> 68 | O19: =N19 -> 68 | P19: =O19 -> 68 | Q19: =P19 -> 68
B20: Changes in operating assets and liabilities (working capital), net of effect of…
C21: Changes in account receivable | D21: -497 | E21: -367 | F21: -652 | G21: -130 | H21: -1124 | I21: -586 | J21: -1083 | K21: -261 | L21: =-('Operating Working Capital'!G9-'Operating Working Capital'!F9) -> -715.48091 | M21: =-('Operating Working Capital'!H9-'Operating Working Capital'!G9) -> -2732.0507 | N21: =-('Operating Working Capital'!I9-'Operating Working Capital'!H9) -> -2005.8829 | O21: =-('Operating Working Capital'!J9-'Operating Working Capital'!I9) -> -2507.3536 | P21: =-('Operating Working Capital'!K9-'Operating Working Capital'!J9) -> -3134.192 | Q21: =-('Operating Working Capital'!L9-'Operating Working Capital'!K9) -> -3917.74
C22: Changes in inventory | D22: -1023 | E22: -429 | F22: -422 | G22: -1709 | H22: -6465 | I22: -1195 | J22: 937 | K22: -630 | L22: =-('Operating Working Capital'!G7-'Operating Working Capital'!F7) -> -2187.8697 | M22: =-('Operating Working Capital'!H7-'Operating Working Capital'!G7) -> -7527.7496 | N22: =-('Operating Working Capital'!I7-'Operating Working Capital'!H7) -> -5526.9048 | O22: =-('Operating Working Capital'!J7-'Operating Working Capital'!I7) -> -6908.631 | P22: =-('Operating Working Capital'!K7-'Operating Working Capital'!J7) -> -8635.7888 | Q22: =-('Operating Working Capital'!L7-'Operating Working Capital'!K7) -> -10794.736
C23: Operating lease vehicles | D23: -215 | E23: -764 | F23: -1072 | G23: -2114 | H23: -1570 | I23: -1952 | J23: -590 | K23: -25 | L23: 0 | M23: 0 | N23: 0 | O23: 0 | P23: 0 | Q23: 0 | R23: READ NOTE
C24: Prepaid expense and other assets | D24: -82 | E24: -288 | F24: -251 | G24: -1540 | H24: -3713 | I24: -2652 | J24: -3273 | K24: -3181 | L24: =-('Operating Working Capital'!G13-'Operating Working Capital'!F13) -> -155.79854 | M24: =-('Operating Working Capital'!H13-'Operating Working Capital'!G13) -> -4012.1501 | N24: =-('Operating Working Capital'!I13-'Operating Working Capital'!H13) -> -2945.7372 | O24: =-('Operating Working Capital'!J13-'Operating Working Capital'!I13) -> -2496.6149 | P24: =-('Operating Working Capital'!K13-'Operating Working Capital'!J13) -> -4306.3252 | Q24: =-('Operating Working Capital'!L13-'Operating Working Capital'!K13) -> -5382.9065
C25: Other non-current assets | D25: -207 | E25: 115 | F25: -344 | G25: 0 | H25: 0 | I25: 0 | J25: 0 | K25: 0 | L25: 0 | M25: 0 | N25: 0 | O25: 0 | P25: 0 | Q25: 0
C26: Changes in accounts payable, accrued and other liabilities | D26: 1797 | E26: 646 | F26: 2102 | G26: 5367 | H26: 8029 | I26: 2605 | J26: 3588 | K26: 4376 | L26: =('Operating Working Capital'!G17-'Operating Working Capital'!F17)+('Operating Working Capital'!G19-'Operating Working Capital'!F19) -> 21869.774 | M26: =('Operating Working Capital'!H17-'Operating Working Capital'!G17)+('Operating Working Capital'!H19-'Operating Working Capital'!G19) -> 24625.22 | N26: =('Operating Working Capital'!I17-'Operating Working Capital'!H17)+('Operating Working Capital'!I19-'Operating Working Capital'!H19) -> 20827.237 | O26: =('Operating Working Capital'!J17-'Operating Working Capital'!I17)+('Operating Working Capital'!J19-'Operating Working Capital'!I19) -> 7677.8683 | P26: =('Operating Working Capital'!K17-'Operating Working Capital'!J17)+('Operating Working Capital'!K19-'Operating Working Capital'!J19) -> 6344.509 | Q26: =('Operating Working Capital'!L17-'Operating Working Capital'!K17)+('Operating Working Capital'!L19-'Operating Working Capital'!K19) -> 23295.342
C27: Deferred revenue | D27: 406 | E27: 801 | F27: 321 | G27: 793 | H27: 1131 | I27: 1532 | J27: 502 | K27: 363 | L27: ='Operating Working Capital'!G21-'Operating Working Capital'!F21 -> -1553.2184 | M27: ='Operating Working Capital'!H21-'Operating Working Capital'!G21 -> 960.67728 | N27: ='Operating Working Capital'!I21-'Operating Working Capital'!H21 -> 532.18024 | O27: ='Operating Working Capital'!J21-'Operating Working Capital'!I21 -> 31.873116 | P27: ='Operating Working Capital'!K21-'Operating Working Capital'!J21 -> -99.512249 | Q27: ='Operating Working Capital'!L21-'Operating Working Capital'!K21 -> 582.30133 | R27: READ NOTE
C28: Customer deposits | D28: -96 | E28: -58 | F28: 7 | G28: 186 | H28: 155 | I28: 0 | J28: 0 | K28: 0
C29: Other long-term liabilities | D29: -25 | E29: -5 | F29: 495 | G29: 0 | H29: 0 | I29: 0 | J29: 0 | K29: 0
C30: Net changes in working capital | D30: =SUM(D21:D29) -> 58 | E30: =SUM(E21:E29) -> -349 | F30: =SUM(F21:F29) -> 184 | G30: =SUM(G21:G29)-G28 -> 667 | H30: =SUM(H21:H29)-H28 -> -3712 | I30: =SUM(I21:I29)-I28 -> -2248 | J30: =SUM(J21:J29)-J28 -> 81 | K30: =SUM(K21:K29)-K28 -> 642 | L30: =SUM(L21:L29)-L28 -> 17257.406 | M30: =SUM(M21:M29)-M28 -> 11313.947 | N30: =SUM(N21:N29)-N28 -> 10880.892 | ... Q30: =SUM(Q21:Q29)-Q28 -> 3782.2607 | R30: READ NOTE
B31: Total cash from operating activities | D31: =D7+SUM(D8:D19)+D30-D10-D16 -> 2098 | E31: =E7+SUM(E8:E19)+E30-E10-E16 -> 2405 | F31: =F7+SUM(F8:F19)+F30-F10-F16 -> 5943 | G31: =G7+SUM(G8:G19)+G30-G10-G16 -> 11497 | H31: =H7+SUM(H8:H19)+H30-H10-H16 -> 14724 | I31: =I7+SUM(I8:I19)+I30-I10-I16 -> 13256 | J31: =J7+SUM(J8:J19)+J30-J10-J16 -> 14923 | K31: =K7+SUM(K8:K19)+K30-K10-K16 -> 14747 | ... Q31: =Q7+SUM(Q8:Q19)+Q30-Q10-Q16 -> 54995.236
A32: Cash flows from investing activities
B33: Purchases of property and equimpent excluding finance lease, net of sales | D33: -2101 | E33: -1327 | F33: -3157 | G33: -6482 | H33: -7158 | I33: -8898 | J33: -11339 | K33: -8527 | R33: When no guidance, You can project CAPEX as a percentage of sales
B34: Purchases of solar energy systems, net of sales | D34: -218 | E34: -105 | F34: -75 | G34: -32 | H34: -5 | I34: -1 | J34: -3 | K34: 0
B35: TOTAL CAPEX | D35: =SUM(D33:D34) -> -2319 | E35: =SUM(E33:E34) -> -1432 | F35: =SUM(F33:F34) -> -3232 | G35: =SUM(G33:G34) -> -6514 | H35: =SUM(H33:H34) -> -7163 | I35: =SUM(I33:I34) -> -8899 | J35: =SUM(J33:J34) -> -11342 | K35: =SUM(K33:K34) -> -8527 | L35: -25000 | M35: -20000 | N35: =-16000 -> -16000 | O35: =N35 -> -16000 | P35: -14000 | Q35: =P35 -> -14000
B36: CAPEX as % of Total Revenues | D36: =-D35/'Income Statement'!E19 -> 0.094352673 | E36: =-E35/'Income Statement'!F19 -> 0.045408422 | F36: =-F35/'Income Statement'!G19 -> 0.060048678 | G36: =-G35/'Income Statement'!H19 -> 0.079963664 | H36: =-H35/'Income Statement'!I19 -> 0.07401858 | I36: =-I35/'Income Statement'!J19 -> 0.091094278 | J36: =-J35/'Income Statement'!K19 -> 0.11960728 | K36: =-K35/'Income Statement'!L19 -> 0.076420505 | L36: =-L35/'Income Statement'!L19 -> 0.22405449 | M36: =L36 -> 0.22405449 | N36: =M36 -> 0.22405449 | O36: =N36 -> 0.22405449 | P36: =O36 -> 0.22405449 | Q36: =P36 -> 0.22405449
B37: Purchase of investments | D37: 0 | E37: 0 | F37: 0 | G37: -132 | H37: -5835 | I37: -19112 | J37: -35955 | K37: -37109 | L37: =K37 -> -37109 | M37: =L37 -> -37109 | N37: =M37 -> -37109 | O37: =N37 -> -37109 | P37: =O37 -> -37109 | Q37: =P37 -> -37109
B38: Proceeds from maturities of investments | D38: 0 | E38: 0 | F38: 0 | G38: 0 | H38: 22 | I38: 12353 | J38: 28310 | K38: 30158 | L38: =7790*3.5 -> 27265 | M38: =L38 -> 27265 | N38: =M38 -> 27265 | O38: =N38 -> 27265 | P38: =O38 -> 27265 | Q38: =P38 -> 27265
B39: Proceeds from sales of investments | G39: 272 | H39: 936 | I39: 138 | J39: 200 | K39: 0 | L39: 0 | M39: 0 | N39: 0 | O39: 0 | P39: 0 | Q39: 0
B40: Receipt of Government grants | D40: 0 | E40: 46 | F40: 123 | G40: 6 | H40: 76 | I40: 0 | J40: =I40 -> 0 | K40: =J40 -> 0
B41: Purchases of nontangible assets | D41: 0 | E41: -5 | F41: -10 | G41: -1500 | H41: -9 | I41: 0 | J41: =I41 -> 0 | K41: =J41 -> 0
B42: Business combinations, net of cash acquired | D42: -18 | E42: -45 | F42: -13 | G42: 0 | H42: 0 | I42: -64 | J42: =H42 -> 0 | K42: 0
...

Sheet Balance Sheet
A2: Consolidated Balance Sheets
A3: ='Cash Flow Statement'!A3 -> (in US$ millions except per share amounts) | G3: Actuals | N3: Estimates
A5: On December 31 | D5: ='Income Statement'!E5 -> 2019 | E5: ='Income Statement'!F5 -> 2020 | F5: ='Income Statement'!G5 -> 2021 | G5: ='Income Statement'!H5 -> 2022 | H5: ='Income Statement'!I5 -> 2023 | I5: ='Income Statement'!J5 -> 2024 | J5: ='Income Statement'!K5 -> 2025 | K5: 2026E | L5: 2027E | M5: 2028E | N5: 2029E | O5: 2030E | P5: 2031E
A6: Assets
B7: Current assets:
C8: Cash and cash equivalents | D8: 6268 | E8: 19384 | F8: 17576 | G8: 16253 | H8: 16398 | I8: 16139 | J8: 16513 | K8: =J8+'Cash Flow Statement'!L61 -> 13579.921 | L8: =K8+'Cash Flow Statement'!M61 -> 16462.705 | M8: =L8+'Cash Flow Statement'!N61 -> 27988.471 | N8: =M8+'Cash Flow Statement'!O61 -> 31442.632 | O8: =N8+'Cash Flow Statement'!P61 -> 39273.977 | P8: =O8+'Cash Flow Statement'!Q61 -> 70619.213
C9: Short-term investments | E9: 0 | F9: 131 | G9: 5932 | H9: 12696 | I9: 20424 | J9: 27546 | K9: =J9-'Cash Flow Statement'!L37-'Cash Flow Statement'!L38-'Cash Flow Statement'!L39 -> 37390 | L9: =K9-'Cash Flow Statement'!M37-'Cash Flow Statement'!M38-'Cash Flow Statement'!M39 -> 47234 | M9: =L9-'Cash Flow Statement'!N37-'Cash Flow Statement'!N38-'Cash Flow Statement'!N39 -> 57078 | N9: =M9-'Cash Flow Statement'!O37-'Cash Flow Statement'!O38-'Cash Flow Statement'!O39 -> 66922 | O9: =N9-'Cash Flow Statement'!P37-'Cash Flow Statement'!P38-'Cash Flow Statement'!P39 -> 76766 | P9: =O9-'Cash Flow Statement'!Q37-'Cash Flow Statement'!Q38-'Cash Flow Statement'!Q39 -> 86610
C10: Prepaid expenses and other current assets | D10: 959 | E10: 1346 | F10: 1723 | G10: 2941 | H10: 3388 | I10: 5362 | J10: 7615 | K10: =J10-'Cash Flow Statement'!L24 -> 7770.7985 | L10: =K10-'Cash Flow Statement'!M24 -> 11782.949 | M10: =L10-'Cash Flow Statement'!N24 -> 14728.686 | N10: =M10-'Cash Flow Statement'!O24 -> 17225.301 | O10: =N10-'Cash Flow Statement'!P24 -> 21531.626 | P10: =O10-'Cash Flow Statement'!Q24 -> 26914.532
C11: Inventories | D11: 3552 | E11: 4101 | F11: 5757 | G11: 12839 | H11: 13626 | I11: 12017 | J11: 12392 | K11: =J11-'Cash Flow Statement'!L22-'Cash Flow Statement'!L12 -> 14193.203 | L11: =K11-'Cash Flow Statement'!M22-'Cash Flow Statement'!M12 -> 21334.286 | M11: =L11-'Cash Flow Statement'!N22-'Cash Flow Statement'!N12 -> 26474.524 | N11: =M11-'Cash Flow Statement'!O22-'Cash Flow Statement'!O12 -> 32996.489 | O11: =N11-'Cash Flow Statement'!P22-'Cash Flow Statement'!P12 -> 41245.611 | P11: =O11-'Cash Flow Statement'!Q22-'Cash Flow Statement'!Q12 -> 51653.68
C12: Accounts receivable, net | D12: 1324 | E12: 1886 | F12: 1913 | G12: 2952 | H12: 3508 | I12: 4418 | J12: 4576 | K12: =J12-'Cash Flow Statement'!L21 -> 5291.4809 | L12: =K12-'Cash Flow Statement'!M21 -> 8023.5316 | M12: =L12-'Cash Flow Statement'!N21 -> 10029.414 | N12: =M12-'Cash Flow Statement'!O21 -> 12536.768 | O12: =N12-'Cash Flow Statement'!P21 -> 15670.96 | P12: =O12-'Cash Flow Statement'!Q21 -> 19588.7
C13: Total current assets | D13: =SUM(D8:D12) -> 12103 | E13: =SUM(E8:E12) -> 26717 | F13: =SUM(F8:F12) -> 27100 | G13: =SUM(G8:G12) -> 40917 | H13: =SUM(H8:H12) -> 49616 | I13: =SUM(I8:I12) -> 58360 | J13: =SUM(J8:J12) -> 68642 | K13: =SUM(K8:K12) -> 78225.403 | ... P13: =SUM(P8:P12) -> 255386.13
B14: Operating leases vehicles, net | D14: 2447 | E14: 3091 | F14: 4511 | G14: 5035 | H14: 5989 | I14: 5581 | J14: 4912 | K14: =J14-'Cash Flow Statement'!L23 -> 4912 | L14: =K14-'Cash Flow Statement'!M23 -> 4912 | M14: =L14-'Cash Flow Statement'!N23 -> 4912 | N14: =M14-'Cash Flow Statement'!O23 -> 4912 | O14: =N14-'Cash Flow Statement'!P23 -> 4912 | P14: =O14-'Cash Flow Statement'!Q23 -> 4912
B15: Energy generation and storage systems (net) | D15: 6138 | E15: 5979 | F15: 5765 | G15: 5489 | H15: 5229 | I15: 4924 | J15: 4604 | K15: =J15-'Cash Flow Statement'!L34 -> 4604 | L15: =K15-'Cash Flow Statement'!M34 -> 4604 | M15: =L15-'Cash Flow Statement'!N34 -> 4604 | N15: =M15-'Cash Flow Statement'!O34 -> 4604 | O15: =N15-'Cash Flow Statement'!P34 -> 4604 | P15: =O15-'Cash Flow Statement'!Q34 -> 4604
B16: Property, plants and equipment, net | D16: 10396 | E16: 12747 | F16: 18884 | G16: 23548 | H16: 29725 | I16: 35836 | J16: 40643 | K16: =J16-'Cash Flow Statement'!L35-'Cash Flow Statement'!L8 -> 57583.861 | L16: =K16-'Cash Flow Statement'!M35-'Cash Flow Statement'!M8 -> 67706.541 | M16: =L16-'Cash Flow Statement'!N35-'Cash Flow Statement'!N8 -> 72495.887 | N16: =M16-'Cash Flow Statement'!O35-'Cash Flow Statement'!O8 -> 75951.9 | O16: =N16-'Cash Flow Statement'!P35-'Cash Flow Statement'!P8 -> 76241.247 | P16: =O16-'Cash Flow Statement'!Q35-'Cash Flow Statement'!Q8 -> 76530.593
B17: Operating leases right-of-use assets | D17: 1218 | E17: 1558 | F17: 2016 | G17: 2563 | H17: 4180 | I17: 5160 | J17: 6027 | K17: =J17 -> 6027 | L17: =K17 -> 6027 | M17: =L17 -> 6027 | N17: =M17 -> 6027 | O17: =N17 -> 6027 | P17: =O17 -> 6027
B18: Digital assets | D18: 0 | E18: 0 | F18: 1260 | G18: 184 | H18: 184 | I18: 1076 | J18: 1008 | K18: =J18-'Cash Flow Statement'!L19 -> 940 | L18: =K18-'Cash Flow Statement'!M19 -> 872 | M18: =L18-'Cash Flow Statement'!N19 -> 804 | N18: =M18-'Cash Flow Statement'!O19 -> 736 | O18: =N18-'Cash Flow Statement'!P19 -> 668 | P18: =O18-'Cash Flow Statement'!Q19 -> 600
B19: Deferred tax assets | D19: 0 | E19: 0 | F19: 0 | G19: 328 | H19: 6733 | I19: 6524 | J19: 6925 | K19: =J19-'Cash Flow Statement'!L18 -> 6802 | L19: =K19-'Cash Flow Statement'!M18 -> 6679 | M19: =L19-'Cash Flow Statement'!N18 -> 6556 | N19: =M19-'Cash Flow Statement'!O18 -> 6433 | O19: =N19-'Cash Flow Statement'!P18 -> 6310 | P19: =O19-'Cash Flow Statement'!Q18 -> 6187
B20: Intangible assets, net | D20: 339 | E20: 313 | F20: 257 | G20: 215 | H20: 178 | I20: 150 | J20: 0 | K20: =J20 -> 0 | L20: =K20 -> 0 | M20: =L20 -> 0 | N20: =M20 -> 0 | O20: =N20 -> 0 | P20: =O20 -> 0
B21: Goodwill | D21: 198 | E21: 207 | F21: 200 | G21: 194 | H21: 253 | I21: 244 | J21: 257 | K21: =J21 -> 257 | L21: =K21 -> 257 | M21: =L21 -> 257 | N21: =M21 -> 257 | O21: =N21 -> 257 | P21: =O21 -> 257
B22: Other non-current assets | D22: 1470 | E22: 1536 | F22: 2138 | G22: 3865 | H22: 4531 | I22: 4215 | J22: =5045-J21 -> 4788 | K22: =J22 -> 4788 | L22: =K22 -> 4788 | M22: =L22 -> 4788 | N22: =M22 -> 4788 | O22: =N22 -> 4788 | P22: =O22 -> 4788
B23: Total assets | D23: =SUM(D14:D22)+D13 -> 34309 | E23: =SUM(E14:E22)+E13 -> 52148 | F23: =SUM(F14:F22)+F13 -> 62131 | G23: =SUM(G14:G22)+G13 -> 82338 | H23: =SUM(H14:H22)+H13 -> 106618 | I23: =SUM(I14:I22)+I13 -> 122070 | J23: =SUM(J14:J22)+J13 -> 137806 | K23: =SUM(K14:K22)+K13 -> 164139.26 | ... P23: =SUM(P14:P22)+P13 -> 359291.72
A24: Liabilities
B25: Current liabilities:
C26: Accounts payable | D26: 3771 | E26: 6051 | F26: 10025 | G26: 15255 | H26: 14431 | I26: 12474 | J26: 13371
C27: Accrued liabilities and other | D27: 3222 | E27: 3855 | F27: 5719 | G27: 7142 | H27: 9080 | I27: 10723 | J27: 13279
C28: Accounts payable, accrued and other liabilities | E28: =E26+E27 -> 9906 | F28: =F26+F27 -> 15744 | G28: =G26+G27 -> 22397 | H28: =H26+H27 -> 23511 | I28: =I26+I27 -> 23197 | J28: =J26+J27 -> 26650 | K28: =J28+'Cash Flow Statement'!L26 -> 48519.774 | L28: =K28+'Cash Flow Statement'!M26 -> 73144.994 | M28: =L28+'Cash Flow Statement'!N26 -> 93972.23 | N28: =M28+'Cash Flow Statement'!O26 -> 101650.1 | O28: =N28+'Cash Flow Statement'!P26 -> 107994.61 | P28: =O28+'Cash Flow Statement'!Q26 -> 131289.95
C29: Deferred revenue | D29: 1163 | E29: 1458 | F29: 1447 | G29: 1747 | H29: 2864 | I29: 3168 | J29: 3424 | K29: =J29+'Cash Flow Statement'!L27 -> 1870.7816 | L29: =K29+'Cash Flow Statement'!M27 -> 2831.4589 | M29: =L29+'Cash Flow Statement'!N27 -> 3363.6391 | N29: =M29+'Cash Flow Statement'!O27 -> 3395.5122 | O29: =N29+'Cash Flow Statement'!P27 -> 3296 | P29: =O29+'Cash Flow Statement'!Q27 -> 3878.3013
C30: Current portion of debt and finance leases | D30: 1785 | E30: 2132 | F30: 1589 | G30: 1502 | H30: 2373 | I30: 2456 | J30: 1640 | K30: =J30 -> 1640 | L30: =K30 -> 1640 | M30: =L30 -> 1640 | N30: =M30 -> 1640 | O30: =N30 -> 1640 | P30: =O30 -> 1640
C31: Customer deposits | D31: 726 | E31: 752 | F31: 925 | G31: 1063 | H31: 0 | I31: =H31 -> 0 | J31: =I31 -> 0 | K31: =J31 -> 0 | L31: =K31 -> 0 | M31: =L31 -> 0 | N31: =M31 -> 0 | O31: =N31 -> 0 | P31: =O31 -> 0
C32: Total current liabilities | D32: =SUM(D26:D31) -> 10667 | E32: =SUM(E26:E31)-E28 -> 14248 | F32: =SUM(F26:F31)-F28 -> 19705 | G32: =SUM(G26:G31)-G28 -> 26709 | H32: =SUM(H26:H31)-H28 -> 28748 | I32: =SUM(I26:I31)-I28 -> 28821 | J32: =SUM(J26:J31)-J28 -> 31714 | K32: =SUM(K28:K31) -> 52030.555 | L32: =SUM(L28:L31) -> 77616.453 | M32: =SUM(M28:M31) -> 98975.87 | N32: =SUM(N28:N31) -> 106685.61 | O32: =SUM(O28:O31) -> 112930.61 | P32: =SUM(P28:P31) -> 136808.25
B33: Debt and finance leases, net of current portion | D33: 11634 | E33: 9556 | F33: 5245 | G33: 1597 | H33: 2857 | I33: 5757 | J33: 6736 | K33: =J33+'Cash Flow Statement'!L15 -> 7008 | L33: =K33+'Cash Flow Statement'!M15 -> 7420.4366 | M33: =L33+'Cash Flow Statement'!N15 -> 7935.9824 | N33: =M33+'Cash Flow Statement'!O15 -> 8580.4147 | O33: =N33+'Cash Flow Statement'!P15 -> 9385.955 | P33: =O33+'Cash Flow Statement'!Q15 -> 10392.88
B34: Deferred revenue, net of current portion | D34: 1207 | E34: 1284 | F34: 2052 | G34: 2804 | H34: 3251 | I34: 3317 | J34: 3631 | K34: =J34 -> 3631 | L34: =K34 -> 3631 | M34: =L34 -> 3631 | N34: =M34 -> 3631 | O34: =N34 -> 3631 | P34: =O34 -> 3631
B35: Other long-term liabilities | D35: 2691 | E35: 3330 | F35: 3546 | G35: 5330 | H35: 8153 | I35: 10495 | J35: 12860 | K35: =J35+'Cash Flow Statement'!L14 -> 12716 | L35: =K35+'Cash Flow Statement'!M14 -> 12643 | M35: =L35+'Cash Flow Statement'!N14 -> 13095 | N35: =M35+'Cash Flow Statement'!O14 -> 12951 | O35: =N35+'Cash Flow Statement'!P14 -> 12878 | P35: =O35+'Cash Flow Statement'!Q14 -> 13330
B36: Total liabilities | D36: =SUM(D33:D35)+D32 -> 26199 | E36: =SUM(E33:E35)+E32 -> 28418 | F36: =SUM(F33:F35)+F32 -> 30548 | G36: =SUM(G33:G35)+G32 -> 36440 | H36: =SUM(H33:H35)+H32 -> 43009 | I36: =SUM(I33:I35)+I32 -> 48390 | J36: =SUM(J33:J35)+J32 -> 54941 | K36: =SUM(K33:K35)+K32 -> 75385.555 | ... P36: =SUM(P33:P35)+P32 -> 164162.13
A37: Commitments and contingencies (Note 15)
A38: Redeemable noncontrolling interests in subsidiaries | D38: 643 | E38: 604 | F38: 568 | G38: 409 | H38: 242 | I38: 63 | J38: 58 | K38: =J38+'Cash Flow Statement'!L57 -> -20 | L38: =K38+'Cash Flow Statement'!M57 -> -98 | M38: =L38+'Cash Flow Statement'!N57 -> -176 | N38: =M38+'Cash Flow Statement'!O57 -> -254 | O38: =N38+'Cash Flow Statement'!P57 -> -332 | P38: =O38+'Cash Flow Statement'!Q57 -> -410
A39: Convertible senior notes | D39: 0 | E39: 51 | F39: 0 | G39: 0 | H39: 0 | I39: 0 | J39: 0 | K39: =J39+'Cash Flow Statement'!L17 -> 0 | L39: =K39+'Cash Flow Statement'!M17 -> 0 | M39: =L39+'Cash Flow Statement'!N17 -> 0 | N39: =M39+'Cash Flow Statement'!O17 -> 0 | O39: =N39+'Cash Flow Statement'!P17 -> 0 | P39: =O39+'Cash Flow Statement'!Q17 -> 0
A40: Stockholders' equity
B41: Preferred stock | D41: 0 | E41: 0 | F41: 0 | G41: 0 | H41: 0 | I41: 0 | J41: 0 | K41: =J41 -> 0 | L41: =K41 -> 0 | M41: =L41 -> 0 | N41: =M41 -> 0 | O41: =N41 -> 0 | P41: =O41 -> 0
B42: Common stock par value + additional paid-in-capital | D42: =12736+1 -> 12737 | E42: =27260+1 -> 27261 | F42: =29803+3 -> 29806 | G42: =32177+3 -> 32180 | H42: =34892+3 -> 34895 | I42: =38371+3 -> 38374 | J42: =42770+3 -> 42773 | K42: =J42+'Cash Flow Statement'!L47+'Cash Flow Statement'!L48+'Cash Flow Statement'!L49 -> 42773 | L42: =K42+'Cash Flow Statement'!M47+'Cash Flow Statement'!M48+'Cash Flow Statement'!M49 -> 42773 | M42: =L42+'Cash Flow Statement'!N47+'Cash Flow Statement'!N48+'Cash Flow Statement'!N49 -> 42773 | N42: =M42+'Cash Flow Statement'!O47+'Cash Flow Statement'!O48+'Cash Flow Statement'!O49 -> 42773 | O42: =N42+'Cash Flow Statement'!P47+'Cash Flow Statement'!P48+'Cash Flow Statement'!P49 -> 42773 | P42: =O42+'Cash Flow Statement'!Q47+'Cash Flow Statement'!Q48+'Cash Flow Statement'!Q49 -> 42874
...

Sheet Depreciation
A2: Depreciation
A3: ='Balance Sheet'!A3 -> (in US$ millions except per share amounts) | D3: Actuals | G3: Estimates
A5: Period Ending December 31 | D5: ='Income Statement'!I5 -> 2023 | E5: ='Income Statement'!J5 -> 2024 | F5: ='Income Statement'!K5 -> 2025 | G5: 2026 | H5: 2027 | I5: 2028 | J5: 2029 | K5: 2030 | L5: 2031
B6: ="Property, plant & equipment on Jan 1 "&G5 -> Property, plant & equipment on Jan 1 2026 | G6: ='Balance Sheet'!J16 -> 40643
B7: Energy generation and storage systems on Jan 1 2026 | G7: ='Balance Sheet'!J15 -> 4604
B8: Operating lease vehicles on Jan 1 2026 | G8: ='Balance Sheet'!J14 -> 4912
B9: Intangible assets as of Jan 1 2026 | G9: 124
B10: Capital expenditures as of Jan 1 of each year | G10: ='Cash Flow Statement'!L35*(-1) -> 25000 | H10: ='Cash Flow Statement'!M35*(-1) -> 20000 | I10: ='Cash Flow Statement'!N35*(-1) -> 16000 | J10: ='Cash Flow Statement'!O35*(-1) -> 16000 | K10: ='Cash Flow Statement'!P35*(-1) -> 14000 | L10: ='Cash Flow Statement'!Q35*(-1) -> 14000
A11: Straight line depreciation | N11: We assume residual values are equal to zero.
B12: Years
C13: Existing PP&E | G13: 11 | M13: All the numbers for the useful lives are assumptions meant to be revisited later.
C14: Energy generation and storage systems | G14: 22
C15: Operating lease vehicles | G15: 3 | M15: IMPORTANT NOTE
C16: Intangible assets | G16: 7
C17: CAPEX | G17: 10 | H17: 11 | I17: 12 | J17: 12 | K17: 12 | L17: 12 | M17: IMPORTANT NOTE 2
B18: Depreciation ($)
C19: Existing PP&E | G19: =$G$6/$G$13 -> 3694.8182 | H19: =$G$6/$G$13 -> 3694.8182 | I19: =$G$6/$G$13 -> 3694.8182 | J19: =$G$6/$G$13 -> 3694.8182 | K19: =$G$6/$G$13 -> 3694.8182 | L19: =$G$6/$G$13 -> 3694.8182
C20: Energy generation and storage systems | G20: =$G$7/$G$14 -> 209.27273 | H20: =$G$7/$G$14 -> 209.27273 | I20: =$G$7/$G$14 -> 209.27273 | J20: =$G$7/$G$14 -> 209.27273 | K20: =$G$7/$G$14 -> 209.27273 | L20: =$G$7/$G$14 -> 209.27273
C21: Operatin lease vehicles | G21: =$G$8/$G$15 -> 1637.3333 | H21: =$G$8/$G$15 -> 1637.3333 | I21: =$G$8/$G$15 -> 1637.3333 | J21: =$G$8/$G$15 -> 1637.3333 | K21: =$G$8/$G$15 -> 1637.3333 | L21: =$G$8/$G$15 -> 1637.3333
C22: Intangible assets | G22: =$G$9/$G$16 -> 17.714286 | H22: =$G$9/$G$16 -> 17.714286 | I22: =$G$9/$G$16 -> 17.714286 | J22: =$G$9/$G$16 -> 17.714286 | K22: =$G$9/$G$16 -> 17.714286 | L22: =$G$9/$G$16 -> 17.714286
C23: =G$5&" CAPEX" -> 2026 CAPEX | G23: =$G$10/$G$17 -> 2500 | H23: =$G$10/$G$17 -> 2500 | I23: =$G$10/$G$17 -> 2500 | J23: =$G$10/$G$17 -> 2500 | K23: =$G$10/$G$17 -> 2500 | L23: =$G$10/$G$17 -> 2500
C24: =H$5&" CAPEX" -> 2027 CAPEX | H24: =$H$10/$H$17 -> 1818.1818 | I24: =$H$10/$H$17 -> 1818.1818 | J24: =$H$10/$H$17 -> 1818.1818 | K24: =$H$10/$H$17 -> 1818.1818 | L24: =$H$10/$H$17 -> 1818.1818
C25: =I$5&" CAPEX" -> 2028 CAPEX | I25: =$I$10/$I$17 -> 1333.3333 | J25: =$I$10/$I$17 -> 1333.3333 | K25: =$I$10/$I$17 -> 1333.3333 | L25: =$I$10/$I$17 -> 1333.3333
C26: =J$5&" CAPEX" -> 2029 CAPEX | J26: =$J$10/$J$17 -> 1333.3333 | K26: =$J$10/$J$17 -> 1333.3333 | L26: =$J$10/$J$17 -> 1333.3333
C27: =K$5&" CAPEX" -> 2030 CAPEX | K27: =K10/K17 -> 1166.6667 | L27: =L10/L17 -> 1166.6667
B28: Total book depreciation | G28: =SUM(G19:G27) -> 8059.1385 | H28: =SUM(H19:H27) -> 9877.3203 | I28: =SUM(I19:I27) -> 11210.654 | J28: =SUM(J19:J27) -> 12543.987 | K28: =SUM(K19:K27) -> 13710.654 | L28: =SUM(L19:L27) -> 13710.654

Sheet Operating Working Capital
A2: Operating Working Capital Schedule (OWC)
A3: =Depreciation!A3 -> (in US$ millions except per share amounts) | D3: Actuals | G3: Estimates
A5: On December 31 | D5: ='Income Statement'!I5 -> 2023 | E5: ='Income Statement'!J5 -> 2024 | F5: ='Income Statement'!K5 -> 2025 | G5: 2026 | H5: 2027 | I5: 2028 | J5: 2029 | K5: 2030 | L5: 2031
A6: Current assets
B7: Inventories | E7: ='Balance Sheet'!I11 -> 12017 | F7: ='Balance Sheet'!J11 -> 12392 | G7: =G8/360*'Income Statement'!L27 -> 14579.87 | H7: =H8/360*'Income Statement'!M27 -> 22107.619 | I7: =I8/360*'Income Statement'!N27 -> 27634.524 | J7: =J8/360*'Income Statement'!O27 -> 34543.155 | K7: =K8/360*'Income Statement'!P27 -> 43178.944 | L7: =L8/360*'Income Statement'!Q27 -> 53973.68
C8: Inventory turnover days | F8: =AVERAGE(E7:F7)/'Income Statement'!K27*360 -> 61.376266 | G8: =F8 -> 61.376266 | H8: =G8 -> 61.376266 | I8: =H8 -> 61.376266 | J8: =I8 -> 61.376266 | K8: =J8 -> 61.376266 | L8: =K8 -> 61.376266
B9: Accounts receivable, net and other | E9: ='Balance Sheet'!I12 -> 4418 | F9: ='Balance Sheet'!J12 -> 4576 | G9: =G10/360*'Income Statement'!L19 -> 5291.4809 | H9: =H10/360*'Income Statement'!M19 -> 8023.5316 | I9: =I10/360*'Income Statement'!N19 -> 10029.414 | J9: =J10/360*'Income Statement'!O19 -> 12536.768 | K9: =K10/360*'Income Statement'!P19 -> 15670.96 | L9: =L10/360*'Income Statement'!Q19 -> 19588.7
C10: Days receivable | F10: =AVERAGE(E9:F9)/'Income Statement'!K19*360 -> 17.072353 | G10: =F10 -> 17.072353 | H10: =G10 -> 17.072353 | I10: =H10 -> 17.072353 | J10: =I10 -> 17.072353 | K10: =J10 -> 17.072353 | L10: =K10 -> 17.072353
B11: Operating lease vehicles | E11: 5581 | F11: 4912 | G11: =F11 -> 4912 | H11: =G11 -> 4912 | I11: =H11 -> 4912 | J11: =I11 -> 4912 | K11: =J11 -> 4912 | L11: =K11 -> 4912 | M11: < revise this line
C12: Lease vehicles days
B13: Prepaid expense and other current assets | E13: ='Balance Sheet'!I10 -> 5362 | F13: ='Balance Sheet'!J10 -> 7615 | G13: =G14/360*'Income Statement'!L41 -> 7770.7985 | H13: =H14/360*'Income Statement'!M41 -> 11782.949 | I13: =I14/360*'Income Statement'!N41 -> 14728.686 | J13: =J14/360*'Income Statement'!O41 -> 17225.301 | K13: =K14/360*'Income Statement'!P41 -> 21531.626 | L13: =L14/360*'Income Statement'!Q41 -> 26914.532
C14: Prepaid expense days | F14: =AVERAGE(E13:F13)/'Income Statement'!K41*360 -> 183.3629 | G14: =F14 -> 183.3629 | H14: =G14 -> 183.3629 | I14: =H14 -> 183.3629 | J14: =I14 -> 183.3629 | K14: =J14 -> 183.3629 | L14: =K14 -> 183.3629
B15: Total current assets | E15: =E7+E9+E13+E11 -> 27378 | F15: =F7+F9+F13+F11 -> 29495 | G15: =G7+G9+G13+G11 -> 32554.149 | H15: =H7+H9+H13+H11 -> 46826.1 | I15: =I7+I9+I13+I11 -> 57304.624 | J15: =J7+J9+J13+J11 -> 69217.224 | K15: =K7+K9+K13+K11 -> 85293.53 | L15: =L7+L9+L13+L11 -> 105388.91
A16: Current liabilities
B17: Accounts payable | E17: ='Balance Sheet'!I26 -> 12474 | F17: ='Balance Sheet'!J26 -> 13371 | G17: =G18/360*'Income Statement'!L27 -> 15437.615 | H17: =H18/360*'Income Statement'!M27 -> 23408.227 | I17: =I18/360*'Income Statement'!N27 -> 29260.284 | J17: =J18/360*'Income Statement'!O27 -> 36575.355 | K17: =K18/360*'Income Statement'!P27 -> 45719.194 | L17: =L18/360*'Income Statement'!Q27 -> 57148.993
C18: Days payable | F18: =AVERAGE(E17:F17)/'Income Statement'!K27*360 -> 64.987078 | G18: =F18 -> 64.987078 | H18: =G18 -> 64.987078 | I18: =H18 -> 64.987078 | J18: =I18 -> 64.987078 | K18: =J18 -> 64.987078 | L18: =K18 -> 64.987078
B19: Accrued liabilities and other | E19: ='Balance Sheet'!I27-993 -> 9730 | F19: ='Balance Sheet'!J27-1311 -> 11968 | G19: =G20/360*'Income Statement'!G27 -> 31771.159 | H19: =H20/360*'Income Statement'!H27 -> 48425.766 | I19: =I20/360*'Income Statement'!I27 -> 63400.946 | J19: =J20/360*'Income Statement'!J27 -> 63763.743 | K19: =K20/360*'Income Statement'!K27 -> 60964.414 | L19: =L20/360*'Income Statement'!L27 -> 72829.957
C20: Accrued days | F20: =AVERAGE(E19:F19)/'Income Statement'!K41*360 -> 306.58921 | G20: =F20 -> 306.58921 | H20: =G20 -> 306.58921 | I20: =H20 -> 306.58921 | J20: =I20 -> 306.58921 | K20: =J20 -> 306.58921 | L20: =K20 -> 306.58921
B21: Deferred revenue | E21: ='Balance Sheet'!I29 -> 3168 | F21: ='Balance Sheet'!J29 -> 3424 | G21: =G22/360*'Income Statement'!G19 -> 1870.7816 | H21: =H22/360*'Income Statement'!H19 -> 2831.4589 | I21: =I22/360*'Income Statement'!I19 -> 3363.6391 | J21: =J22/360*'Income Statement'!J19 -> 3395.5122 | K21: =K22/360*'Income Statement'!K19 -> 3296 | L21: =L22/360*'Income Statement'!L19 -> 3878.3013
C22: Deferred revenue days | F22: =AVERAGE(E21:F21)/'Income Statement'!K19*360 -> 12.512892 | G22: =F22 -> 12.512892 | H22: =G22 -> 12.512892 | I22: =H22 -> 12.512892 | J22: =I22 -> 12.512892 | K22: =J22 -> 12.512892 | L22: =K22 -> 12.512892
B23: Customer deposits | E23: ='Balance Sheet'!I31 -> 0 | F23: ='Balance Sheet'!J31 -> 0 | G23: =G24/360*'Income Statement'!G19 -> 0 | H23: =H24/360*'Income Statement'!H19 -> 0 | I23: =I24/360*'Income Statement'!I19 -> 0 | J23: =J24/360*'Income Statement'!J19 -> 0 | K23: =K24/360*'Income Statement'!K19 -> 0 | L23: =L24/360*'Income Statement'!L19 -> 0
C24: Customer deposits days | F24: =AVERAGE(E23:F23)/'Income Statement'!F19*360 -> 0 | G24: =F24 -> 0 | H24: =G24 -> 0 | I24: =H24 -> 0 | J24: =I24 -> 0 | K24: =J24 -> 0 | L24: =K24 -> 0
B25: Total current liabilities | E25: =E17+E19+E21+E23 -> 25372 | F25: =F17+F19+F21+F23 -> 28763 | G25: =G17+G19+G21+G23 -> 49079.555 | H25: =H17+H19+H21+H23 -> 74665.453 | I25: =I17+I19+I21+I23 -> 96024.87 | J25: =J17+J19+J21+J23 -> 103734.61 | K25: =K17+K19+K21+K23 -> 109979.61 | L25: =L17+L19+L21+L23 -> 133857.25
B26: Total operating working capital | E26: =E15-E25 -> 2006 | F26: =F15-F25 -> 732 | G26: =G15-G25 -> -16525.406 | H26: =H15-H25 -> -27839.353 | I26: =I15-I25 -> -38720.245 | J26: =J15-J25 -> -34517.387 | K26: =K15-K25 -> -24686.078 | L26: =L15-L25 -> -28468.338
B27: Change in total operating working capital | F27: =F26-E26 -> -1274 | G27: =G26-F26 -> -17257.406 | H27: =H26-G26 -> -11313.947 | I27: =I26-H26 -> -10880.892 | J27: =J26-I26 -> 4202.8582 | K27: =K26-J26 -> 9831.3093 | L27: =L26-K26 -> -3782.2607
B28: Match? (Y/N) | G28: =IF(ROUND(-G27-'Cash Flow Statement'!L30,1)=0,"Y","N") -> Y | H28: =IF(ROUND(-H27-'Cash Flow Statement'!M30,1)=0,"Y","N") -> Y | I28: =IF(ROUND(-I27-'Cash Flow Statement'!N30,1)=0,"Y","N") -> Y | J28: =IF(ROUND(-J27-'Cash Flow Statement'!O30,1)=0,"Y","N") -> Y | K28: =IF(ROUND(-K27-'Cash Flow Statement'!P30,1)=0,"Y","N") -> Y | L28: =IF(ROUND(-L27-'Cash Flow Statement'!Q30,1)=0,"Y","N") -> Y

Sheet Debt Schedule
A2: Debt Schedule
A3: ='Operating Working Capital'!A3 -> (in US$ millions except per share amounts) | D3: Actuals | G3: Estimates
A5: Period Ending December 31 | D5: ='Income Statement'!I5 -> 2023 | E5: ='Income Statement'!J5 -> 2024 | F5: ='Income Statement'!K5 -> 2025 | G5: ='Income Statement'!L5 -> 2026 | H5: ='Income Statement'!M5 -> 2027 | I5: ='Income Statement'!N5 -> 2028 | J5: ='Income Statement'!O5 -> 2029 | K5: ='Income Statement'!P5 -> 2030 | L5: ='Income Statement'!Q5 -> 2031
A6: Cash available to pay down debt
B7: Cash at beginning of year | G7: =F49 -> 16513 | H7: =G49 -> 13579.921 | I7: =H49 -> 16462.705 | J7: =I49 -> 27988.471 | K7: =J49 -> 31442.632 | L7: =K49 -> 39273.977
B8: Cash flow before debt paydown | G8: ='Cash Flow Statement'!L65 -> -2933.0793 | H8: ='Cash Flow Statement'!M65 -> 2882.7848 | I8: ='Cash Flow Statement'!N65 -> 11525.765 | J8: ='Cash Flow Statement'!O65 -> 3454.1612 | K8: ='Cash Flow Statement'!P65 -> 7831.3446 | L8: ='Cash Flow Statement'!Q65 -> 31244.236
B9: Minimum cash cushion | G9: -18000 | H9: -18000 | I9: -25000 | J9: -30000 | K9: -30000 | L9: -30000
B10: Total cash available to pay down debt | G10: =SUM(G7:G9) -> -4420.0793 | H10: =SUM(H7:H9) -> -1537.2945 | I10: =SUM(I7:I9) -> 2988.4707 | J10: =SUM(J7:J9) -> 1442.6319 | K10: =SUM(K7:K9) -> 9273.9765 | L10: =SUM(L7:L9) -> 40518.213
A11: Current portion of debt and finance leases / revolver
B12: Short term debt (beginning of year) | G12: =F17 -> 1569 | H12: =G17 -> 1569 | I12: =H17 -> 1569 | J12: =I17 -> 1569 | K12: =J17 -> 1569 | L12: =K17 -> 1569
B13: Mandatory issuances | G13: 0 | H13: 0 | I13: 0 | J13: 0 | K13: 0 | L13: 0
B14: Mandatory (retirements) | G14: 0 | H14: 0 | I14: 0 | J14: 0 | K14: 0 | L14: 0
B15: Non-mandatory issuances | G15: 0 | H15: 0 | I15: 0 | J15: 0 | K15: 0 | L15: 0
B16: Non-mandatory (retirements) | G16: 0 | H16: 0 | I16: 0 | J16: 0 | K16: 0 | L16: 0
B17: Current portion of debt and finance leases (end of year) | F17: ='Balance Sheet'!J30-F35 -> 1569 | G17: =SUM(G12:G16) -> 1569 | H17: =SUM(H12:H16) -> 1569 | I17: =SUM(I12:I16) -> 1569 | J17: =SUM(J12:J16) -> 1569 | K17: =SUM(K12:K16) -> 1569 | L17: =SUM(L12:L16) -> 1569
B18: Current portion of debt and finance leases interest expense | G18: =AVERAGE(G12,G17)*G19 -> 40.7959 | H18: =AVERAGE(H12,H17)*H19 -> 40.7959 | I18: =AVERAGE(I12,I17)*I19 -> 40.7959 | J18: =AVERAGE(J12,J17)*J19 -> 40.7959 | K18: =AVERAGE(K12,K17)*K19 -> 40.7959 | L18: =AVERAGE(L12,L17)*L19 -> 40.7959
C19: Current portion interest rate | G19: =(1*0.047+1492*0.0247+55*0.0508+21*0.0525)/(1+1492+55+21) -> 0.026001211 | H19: =(1*0.047+1492*0.0247+55*0.0508+21*0.0525)/(1+1492+55+21) -> 0.026001211 | I19: =(1*0.047+1492*0.0247+55*0.0508+21*0.0525)/(1+1492+55+21) -> 0.026001211 | J19: =(1*0.047+1492*0.0247+55*0.0508+21*0.0525)/(1+1492+55+21) -> 0.026001211 | K19: =(1*0.047+1492*0.0247+55*0.0508+21*0.0525)/(1+1492+55+21) -> 0.026001211 | L19: =(1*0.047+1492*0.0247+55*0.0508+21*0.0525)/(1+1492+55+21) -> 0.026001211
A20: Debt, net of current portion
B21: Long term debt (beginning of year) | G21: =F26 -> 6584 | H21: =G26 -> 6584 | I21: =H26 -> 6584 | J21: =I26 -> 6584 | K21: =J26 -> 6584 | L21: =K26 -> 6584
B22: Mandatory issuances | G22: 0 | H22: 0 | I22: 0 | J22: 0 | K22: 0 | L22: 0
B23: Mandatory (retirements) | G23: 0 | H23: 0 | I23: 0 | J23: 0 | K23: 0 | L23: 0
B24: Non-mandatory issuances | G24: 0 | H24: 0 | I24: 0 | J24: 0 | K24: 0 | L24: 0
B25: Non-mandatory (retirements) | G25: 0 | H25: 0 | I25: 0 | J25: 0 | K25: 0 | L25: 0
B26: Long-term debt (end of year) | F26: ='Balance Sheet'!J33-F44 -> 6584 | G26: =SUM(G21:G25) -> 6584 | H26: =SUM(H21:H25) -> 6584 | I26: =SUM(I21:I25) -> 6584 | J26: =SUM(J21:J25) -> 6584 | K26: =SUM(K21:K25) -> 6584 | L26: =SUM(L21:L25) -> 6584
B27: Long term interest expense | G27: =AVERAGE(G21,G26)*G28 -> 238.618 | H27: =AVERAGE(H21,H26)*H28 -> 238.618 | I27: =AVERAGE(I21,I26)*I28 -> 238.618 | J27: =AVERAGE(J21,J26)*J28 -> 238.618 | K27: =AVERAGE(K21,K26)*K28 -> 238.618 | L27: =AVERAGE(L21,L26)*L28 -> 238.618
C28: Long term interest rate | G28: =(2*0.0575+1745*0.0657+4288*0.0211+337*0.0625+212*0.0581)/(2+1745+4288+337+212) -> 0.036242102 | H28: =(2*0.0575+1745*0.0657+4288*0.0211+337*0.0625+212*0.0581)/(2+1745+4288+337+212) -> 0.036242102 | I28: =(2*0.0575+1745*0.0657+4288*0.0211+337*0.0625+212*0.0581)/(2+1745+4288+337+212) -> 0.036242102 | J28: =(2*0.0575+1745*0.0657+4288*0.0211+337*0.0625+212*0.0581)/(2+1745+4288+337+212) -> 0.036242102 | K28: =(2*0.0575+1745*0.0657+4288*0.0211+337*0.0625+212*0.0581)/(2+1745+4288+337+212) -> 0.036242102 | L28: =(2*0.0575+1745*0.0657+4288*0.0211+337*0.0625+212*0.0581)/(2+1745+4288+337+212) -> 0.036242102
A29: Short term finance leases
B30: Short term finance leases (beginning of year) | G30: =F35 -> 71 | H30: =G35 -> 71 | I30: =H35 -> 71 | J30: =I35 -> 71 | K30: =J35 -> 71 | L30: =K35 -> 71
B31: Mandatory issuances | G31: 0 | H31: 0 | I31: 0 | J31: 0 | K31: 0 | L31: 0
B32: Mandatory (retirements) | G32: 0 | H32: 0 | I32: 0 | J32: 0 | K32: 0 | L32: 0
B33: Non-mandatory issuances | G33: 0 | H33: 0 | I33: 0 | J33: 0 | K33: 0 | L33: 0
B34: Non-mandatory (retirements) | G34: 0 | H34: 0 | I34: 0 | J34: 0 | K34: 0 | L34: 0
B35: Short term leases (end of year) | F35: 71 | G35: =SUM(G30:G34) -> 71 | H35: =SUM(H30:H34) -> 71 | I35: =SUM(I30:I34) -> 71 | J35: =SUM(J30:J34) -> 71 | K35: =SUM(K30:K34) -> 71 | L35: =SUM(L30:L34) -> 71
B36: Short term leases interest expense | G36: =AVERAGE(G30,G35)*G37 -> 3.337 | H36: =AVERAGE(H30,H35)*H37 -> 3.337 | I36: =AVERAGE(I30,I35)*I37 -> 3.337 | J36: =AVERAGE(J30,J35)*J37 -> 3.337 | K36: =AVERAGE(K30,K35)*K37 -> 3.337 | L36: =AVERAGE(L30,L35)*L37 -> 3.337
C37: Short term leases interest rate | G37: 0.047 | H37: 0.047 | I37: 0.047 | J37: 0.047 | K37: 0.047 | L37: 0.047
A38: Long term finance leases
B39: Long term finance leases (beginning of year) | G39: =F44 -> 152 | H39: =G44 -> 152 | I39: =H44 -> 152 | J39: =I44 -> 152 | K39: =J44 -> 152 | L39: =K44 -> 152
B40: Mandatory issuances | G40: 0 | H40: 0 | I40: 0 | J40: 0 | K40: 0 | L40: 0
B41: Mandatory (retirements) | G41: 0 | H41: 0 | I41: 0 | J41: 0 | K41: 0 | L41: 0
B42: Non-mandatory issuances | G42: 0 | H42: 0 | I42: 0 | J42: 0 | K42: 0 | L42: 0
...

Sheet ---> Valuation

Sheet DCF Analysis
A2: Discounted Cash Flow Analysis
A3: ='Debt Schedule'!A3 -> (in US$ millions except per share amounts) | D3: Actuals | G3: Estimates
A5: Period Ending January 31 | D5: 2023 | E5: =D5+1 -> 2024 | F5: =E5+1 -> 2025 | G5: =F5+1 -> 2026 | H5: =G5+1 -> 2027 | I5: =H5+1 -> 2028 | J5: =I5+1 -> 2029 | K5: =J5+1 -> 2030
A6: Unlevered Free Cash Flow
B7: EBIT | G7: ='Income Statement'!L46 -> 2746.6645 | H7: ='Income Statement'!M46 -> 6507.6394 | I7: ='Income Statement'!N46 -> 9270.546 | J7: ='Income Statement'!O46 -> 15385.139 | K7: ='Income Statement'!P46 -> 21200.754
B8: Depreciation & Amortization | G8: ='Cash Flow Statement'!L8 -> 8059.1385 | H8: ='Cash Flow Statement'!M8 -> 9877.3203 | I8: ='Cash Flow Statement'!N8 -> 11210.654 | J8: ='Cash Flow Statement'!O8 -> 12543.987 | K8: ='Cash Flow Statement'!P8 -> 13710.654
B9: Deferred Taxes | G9: ='Cash Flow Statement'!L18 -> 123 | H9: ='Cash Flow Statement'!M18 -> 123 | I9: ='Cash Flow Statement'!N18 -> 123 | J9: ='Cash Flow Statement'!O18 -> 123 | K9: ='Cash Flow Statement'!P18 -> 123
B10: Other | G10: ='Cash Flow Statement'!L9+'Cash Flow Statement'!L15 -> 3655.2944 | H10: ='Cash Flow Statement'!M9+'Cash Flow Statement'!M15 -> 5542.5638 | I10: ='Cash Flow Statement'!N9+'Cash Flow Statement'!N15 -> 6928.2047 | J10: ='Cash Flow Statement'!O9+'Cash Flow Statement'!O15 -> 8144.0815 | K10: ='Cash Flow Statement'!P9+'Cash Flow Statement'!P15 -> 10180.102
B11: Changes in Working Capital | G11: ='Cash Flow Statement'!L30 -> 17257.406 | H11: ='Cash Flow Statement'!M30 -> 11313.947 | I11: ='Cash Flow Statement'!N30 -> 10880.892 | J11: ='Cash Flow Statement'!O30 -> -4202.8582 | K11: ='Cash Flow Statement'!P30 -> -9831.3093
B12: Capital Expenditures | G12: ='Cash Flow Statement'!L35 -> -25000 | H12: ='Cash Flow Statement'!M35 -> -20000 | I12: ='Cash Flow Statement'!N35 -> -16000 | J12: ='Cash Flow Statement'!O35 -> -16000 | K12: ='Cash Flow Statement'!P35 -> -14000
B13: Taxes | G13: =-G7*'Income Statement'!L56 -> -740.52739 | H13: =-H7*'Income Statement'!M56 -> -1754.5227 | I13: =-I7*'Income Statement'!N56 -> -2499.4291 | J13: =-J7*'Income Statement'!O56 -> -4147.9828 | K13: =-K7*'Income Statement'!P56 -> -5715.9289
A14: Total Unlevered Free Cash Flow | G14: =SUM(G7:G13) -> 6100.976 | H14: =SUM(H7:H13) -> 11609.948 | I14: =SUM(I7:I13) -> 19913.867 | J14: =SUM(J7:J13) -> 11845.367 | K14: =SUM(K7:K13) -> 15667.271
A15: Net Present Value Calulation
B16: Period | G16: 1 | H16: 2 | I16: 3 | J16: 4 | K16: 5
B17: Discounted Cash Flow | F17: =L27 -> 0.11500994 | G17: =G14/(1+$F$17)^G16 -> 5471.6786 | H17: =H14/(1+$F$17)^H16 -> 9338.407 | I17: =I14/(1+$F$17)^I16 -> 14365.455 | J17: =J14/(1+$F$17)^J16 -> 7663.6129 | K17: =K14/(1+$F$17)^K16 -> 9090.7492
B18: Total Net Present Value | G18: =SUM(G17:K17) -> 45929.903
B19: Terminal Value
B20: EBITDA Method | J20: Cost of Capital
C21: Exit Year EBITDA | F21: =K7+K8 -> 34911.408 | J21: Risk Free Rate | L21: 0.04505 | M21: Debt YE 2025 | O21: ='Balance Sheet'!J30+'Balance Sheet'!J33 -> 8376
C22: Multiple | F22: =(O21+O24-'Balance Sheet'!J8)/'Income Statement'!K42 -> 135.2832 | J22: Market Risk Premium | L22: 0.0503 | M22: Stock Price | O22: 405.05
C23: Terminal Value | F23: =F22*F21 -> 4722926.8 | J23: Beta | L23: 1.4 | M23: Shares Outstanding | O23: ='Income Statement'!K74 -> 3528
C24: Net Present Value | F24: =F23/(1+F17)^K16 -> 2740422.5 | J24: Cost of Equity | L24: =L22*L23+L21 -> 0.11547 | M24: Equity Value | O24: =O22*O23 -> 1429016.4
B25: Perpetuity Method | J25: Cost of Debt | L25: 0.05
C26: Unlevered Free Cash Flow | F26: =K14 -> 15667.271
C27: Growth Rate | F27: 0.025 | J27: WACC | L27: =O24/(O24+O21)*L24+O21/(O21+O24)*L25*(1-'Income Statement'!K56) -> 0.11500994
C28: Terminal Value | F28: =F26*(1+F27)/(F17-F27) -> 178413.11
C29: Net Present Value | F29: =F28/(1+F17)^K16 -> 103522.1
B31: Discounted Cash Flow Total Valuation | E31: EBITDA Method | F31: Perpetuity Method
B32: Total of Present Value of Cash Flows | E32: =G18 -> 45929.903 | F32: =G18 -> 45929.903
B33: Present Value of Terminal Value | E33: =F24 -> 2740422.5 | F33: =F29 -> 103522.1
B34: Total Enterprise Value | E34: =E32+E33 -> 2786352.4 | F34: =F32+F33 -> 149452
B35: Net Debt, Non-controlling interests, preferred securities | E35: =O21-'Balance Sheet'!J8-'Balance Sheet'!J9 -> -35683 | F35: =E35 -> -35683
B36: Equity Value | E36: =E34-E35 -> 2822035.4 | F36: =F34-F35 -> 185135
B37: Share Count (millions) | E37: =O23 -> 3528 | F37: =O23 -> 3528
B38: Estimated Equity Value per Share | E38: =E36/E37 -> 799.89665 | F38: =F36/F37 -> 52.475908

Sheet Comparable Companies Anaylsis
A2: Comparable Companies Analysis
A3: (in US$ millions)
C4: Current Stock Price$ | D4: Market Capitalization (Value)$ | E4: Enterprise | F4: Price / Earnings | I4: E.V. / Revenue | L4: E.V. / EBIT | O4: E.V. / EBITDA
E5: Value | F5: =C25 -> 20A | G5: =D25 -> LTM | H5: =E25 -> 21E | I5: =F25 -> 20A | J5: =G25 -> LTM | K5: =H25 -> 21E | L5: =I5 -> 20A | M5: =J5 -> LTM | N5: =K5 -> 21E | O5: =I25 -> 20A | P5: =J25 -> LTM | Q5: =K25 -> 21E
B6: Company | E6: $MM | F6: x | G6: x | H6: x | I6: x | J6: x | K6: x | L6: x | M6: x | N6: x | O6: x | P6: x | Q6: x
B7: Amazon | C7: =#REF! -> #REF! | D7: =#REF! -> #REF! | E7: =#REF! -> #REF! | F7: =$C7/L27 -> #REF! | G7: =$C7/M27 -> #REF! | H7: =$C7/N27 -> #REF! | I7: =$E7/C27 -> #REF! | J7: =$E7/D27 -> #REF! | K7: =$E7/E27 -> #REF! | L7: =$E7/F27 -> #REF! | M7: =$E7/G27 -> #REF! | N7: =$E7/H27 -> #REF! | O7: =$E7/I27 -> #REF! | P7: =$E7/J27 -> #REF! | Q7: =$E7/K27 -> #REF!
B8: Group 1: Retail / E-Commerce
B9: Ebay | C9: =#REF! -> #REF! | D9: =#REF! -> #REF! | E9: =#REF! -> #REF! | F9: =$C9/L28 -> #REF! | G9: =$C9/M28 -> #REF! | H9: =$C9/N28 -> #REF! | I9: =$E9/C28 -> #REF! | J9: =$E9/D28 -> #REF! | K9: =$E9/E28 -> #REF! | L9: =$E9/F28 -> #REF! | M9: =$E9/G28 -> #REF! | N9: =$E9/H28 -> #REF! | O9: =$E9/I28 -> #REF! | P9: =$E9/J28 -> #REF! | Q9: =$E9/K28 -> #REF!
B10: Etsy | C10: =#REF! -> #REF! | D10: =#REF! -> #REF! | E10: =#REF! -> #REF! | F10: =$C10/L29 -> #REF! | G10: =$C10/M29 -> #REF! | H10: =$C10/N29 -> #REF! | I10: =$E10/C29 -> #REF! | J10: =$E10/D29 -> #REF! | K10: =$E10/E29 -> #REF! | L10: =$E10/F29 -> #REF! | M10: =$E10/G29 -> #REF! | N10: =$E10/H29 -> #REF! | O10: =$E10/I29 -> #REF! | P10: =$E10/J29 -> #REF! | Q10: =$E10/K29 -> #REF!
B11: Walmart | C11: =#REF! -> #REF! | D11: =#REF! -> #REF! | E11: =#REF! -> #REF! | F11: =$C11/L30 -> #REF! | G11: =$C11/M30 -> #REF! | H11: =$C11/N30 -> #REF! | I11: =$E11/C30 -> #REF! | J11: =$E11/D30 -> #REF! | K11: =$E11/E30 -> #REF! | L11: =$E11/F30 -> #REF! | M11: =$E11/G30 -> #REF! | N11: =$E11/H30 -> #REF! | O11: =$E11/I30 -> #REF! | P11: =$E11/J30 -> #REF! | Q11: =$E11/K30 -> #REF!
B12: Target | C12: =#REF! -> #REF! | D12: =#REF! -> #REF! | E12: =#REF! -> #REF! | F12: =$C12/L31 -> #REF! | G12: =$C12/M31 -> #REF! | H12: =$C12/N31 -> #REF! | I12: =$E12/C31 -> #REF! | J12: =$E12/D31 -> #REF! | K12: =$E12/E31 -> #REF! | L12: =$E12/F31 -> #REF! | M12: =$E12/G31 -> #REF! | N12: =$E12/H31 -> #REF! | O12: =$E12/I31 -> #REF! | P12: =$E12/J31 -> #REF! | Q12: =$E12/K31 -> #REF!
B13: Best Buy | C13: =#REF! -> #REF! | D13: =#REF! -> #REF! | E13: =#REF! -> #REF! | F13: =$C13/L32 -> #REF! | G13: =$C13/M32 -> #REF! | H13: =$C13/N32 -> #REF! | I13: =$E13/C32 -> #REF! | J13: =$E13/D32 -> #REF! | K13: =$E13/E32 -> #REF! | L13: =$E13/F32 -> #REF! | M13: =$E13/G32 -> #REF! | N13: =$E13/H32 -> #REF! | O13: =$E13/I32 -> #REF! | P13: =$E13/J32 -> #REF! | Q13: =$E13/K32 -> #REF!
B14: Group 2: Subscription / Web Services
B15: Google | C15: ='GOOG Comp'!D49 -> 2527.37 | D15: ='GOOG Comp'!D59 -> 1831976.3 | E15: ='GOOG Comp'!D67 -> 1710759.3 | F15: =$C15/L33 -> 51.511628 | G15: =$C15/M33 -> 43.266152 | H15: =$C15/N33 -> 37.50036 | I15: =$E15/C33 -> 9.3726367 | J15: =$E15/D33 -> 8.6980977 | K15: =$E15/E33 -> 6.8263923 | L15: =$E15/F33 -> 41.499109 | M15: =$E15/G33 -> 34.4328 | N15: =$E15/H33 -> 30.225134 | O15: =$E15/I33 -> 31.605226 | P15: =$E15/J33 -> 27.489142 | Q15: =$E15/K33 -> 23.019101
B16: Netflix
B17: IBM | C17: =#REF! -> #REF! | D17: =#REF! -> #REF! | E17: =#REF! -> #REF! | F17: =$C17/L35 -> #REF! | G17: NM | H17: =$C17/N35 -> #REF! | I17: =$E17/C35 -> #REF! | J17: =$E17/D35 -> #REF! | K17: =$E17/E35 -> #REF! | L17: =$E17/F35 -> #REF! | M17: =$E17/G35 -> #REF! | N17: =$E17/H35 -> #REF! | O17: =$E17/I35 -> #REF! | P17: =$E17/J35 -> #REF! | Q17: =$E17/K35 -> #REF!
B18: Median | F18: =MEDIAN(F9:F17) -> #REF! | G18: =MEDIAN(G9:G17) -> #REF! | H18: =MEDIAN(H9:H17) -> #REF! | I18: =MEDIAN(I9:I17) -> #REF! | J18: =MEDIAN(J9:J17) -> #REF! | K18: =MEDIAN(K9:K17) -> #REF! | L18: =MEDIAN(L9:L17) -> #REF! | M18: =MEDIAN(M9:M17) -> #REF! | ... Q18: =MEDIAN(Q9:Q17) -> #REF!
B19: High | F19: =MAX(F9:F17) -> #REF! | G19: =MAX(G9:G17) -> #REF! | H19: =MAX(H9:H17) -> #REF! | I19: =MAX(I9:I17) -> #REF! | J19: =MAX(J9:J17) -> #REF! | K19: =MAX(K9:K17) -> #REF! | L19: =MAX(L9:L17) -> #REF! | M19: =MAX(M9:M17) -> #REF! | ... Q19: =MAX(Q9:Q17) -> #REF!
